2025-10-19 14:47:33,221 INFO    MainThread:3166 [wandb_setup.py:_flush():81] Current SDK version is 0.22.2
2025-10-19 14:47:33,221 INFO    MainThread:3166 [wandb_setup.py:_flush():81] Configure stats pid to 3166
2025-10-19 14:47:33,221 INFO    MainThread:3166 [wandb_setup.py:_flush():81] Loading settings from /root/.config/wandb/settings
2025-10-19 14:47:33,221 INFO    MainThread:3166 [wandb_setup.py:_flush():81] Loading settings from /root/autodl-tmp/PPPUE/wandb/settings
2025-10-19 14:47:33,221 INFO    MainThread:3166 [wandb_setup.py:_flush():81] Loading settings from environment variables
2025-10-19 14:47:33,221 INFO    MainThread:3166 [wandb_init.py:setup_run_log_directory():705] Logging user logs to /root/autodl-tmp/PPPUE/wandb/run-20251019_144733-s6xi2w0j/logs/debug.log
2025-10-19 14:47:33,221 INFO    MainThread:3166 [wandb_init.py:setup_run_log_directory():706] Logging internal logs to /root/autodl-tmp/PPPUE/wandb/run-20251019_144733-s6xi2w0j/logs/debug-internal.log
2025-10-19 14:47:33,221 INFO    MainThread:3166 [wandb_init.py:init():832] calling init triggers
2025-10-19 14:47:33,221 INFO    MainThread:3166 [wandb_init.py:init():837] wandb.init called with sweep_config: {}
config: {'learning_rate_uem': 1e-05, 'learning_rate_lora': 0.0001, 'epochs': 10, 'batch_size': 1, 'prefix_length': 5, 'clipping_norm': 1.0, 'distillation_temp': 1.0, 'lora_r': 16, 'lora_alpha': 32, 'lora_dropout': 0.1, 'llm_model': '/root/autodl-tmp/huggingface/hub/models--meta-llama--Meta-Llama-3-8B-Instruct/snapshots/8afb486c1db24fe5011ec46dfbe5b5dccdb575c2', 'uem_model': '/root/autodl-tmp/huggingface/hub/models--BAAI--bge-large-en-v1.5/snapshots/d4aa6901d3a41ba39fb536a557fa166f842b0e09', '_wandb': {}}
2025-10-19 14:47:33,221 INFO    MainThread:3166 [wandb_init.py:init():880] starting backend
2025-10-19 14:47:33,444 INFO    MainThread:3166 [wandb_init.py:init():883] sending inform_init request
2025-10-19 14:47:33,461 INFO    MainThread:3166 [wandb_init.py:init():891] backend started and connected
2025-10-19 14:47:33,463 INFO    MainThread:3166 [wandb_init.py:init():961] updated telemetry
2025-10-19 14:47:33,475 INFO    MainThread:3166 [wandb_init.py:init():985] communicating run to backend with 90.0 second timeout
2025-10-19 14:47:34,677 INFO    MainThread:3166 [wandb_init.py:init():1036] starting run threads in backend
2025-10-19 14:47:34,750 INFO    MainThread:3166 [wandb_run.py:_console_start():2509] atexit reg
2025-10-19 14:47:34,751 INFO    MainThread:3166 [wandb_run.py:_redirect():2357] redirect: wrap_raw
2025-10-19 14:47:34,751 INFO    MainThread:3166 [wandb_run.py:_redirect():2426] Wrapping output streams.
2025-10-19 14:47:34,751 INFO    MainThread:3166 [wandb_run.py:_redirect():2449] Redirects installed.
2025-10-19 14:47:34,753 INFO    MainThread:3166 [wandb_init.py:init():1076] run started, returning control to user process
2025-10-19 15:57:32,176 INFO    wandb-AsyncioManager-main:3166 [service_client.py:_forward_responses():80] Reached EOF.
2025-10-19 15:57:32,176 INFO    wandb-AsyncioManager-main:3166 [mailbox.py:close():137] Closing mailbox, abandoning 1 handles.
2025-10-19 15:57:37,864 ERROR   MainThread:3166 [redirect.py:_on_write():664] [all runs] error in stderr callback
Traceback (most recent call last):
  File "/root/miniconda3/envs/llm/lib/python3.9/site-packages/wandb/sdk/lib/redirect.py", line 662, in _on_write
    cb(written_data)
  File "/root/miniconda3/envs/llm/lib/python3.9/site-packages/wandb/sdk/wandb_run.py", line 2436, in <lambda>
    lambda data: self._console_raw_callback("stderr", data),
  File "/root/miniconda3/envs/llm/lib/python3.9/site-packages/wandb/sdk/wandb_run.py", line 399, in wrapper
    return func(self, *args, **kwargs)
  File "/root/miniconda3/envs/llm/lib/python3.9/site-packages/wandb/sdk/wandb_run.py", line 457, in wrapper_fn
    return func(self, *args, **kwargs)
  File "/root/miniconda3/envs/llm/lib/python3.9/site-packages/wandb/sdk/wandb_run.py", line 1595, in _console_raw_callback
    self._backend.interface.publish_output_raw(name, data)
  File "/root/miniconda3/envs/llm/lib/python3.9/site-packages/wandb/sdk/interface/interface.py", line 802, in publish_output_raw
    self._publish_output_raw(o)
  File "/root/miniconda3/envs/llm/lib/python3.9/site-packages/wandb/sdk/interface/interface_shared.py", line 37, in _publish_output_raw
    self._publish(rec)
  File "/root/miniconda3/envs/llm/lib/python3.9/site-packages/wandb/sdk/interface/interface_sock.py", line 43, in _publish
    self._asyncer.run(lambda: self._client.publish(request))
  File "/root/miniconda3/envs/llm/lib/python3.9/site-packages/wandb/sdk/lib/asyncio_manager.py", line 136, in run
    return future.result()
  File "/root/miniconda3/envs/llm/lib/python3.9/concurrent/futures/_base.py", line 446, in result
    return self.__get_result()
  File "/root/miniconda3/envs/llm/lib/python3.9/concurrent/futures/_base.py", line 391, in __get_result
    raise self._exception
  File "/root/miniconda3/envs/llm/lib/python3.9/site-packages/wandb/sdk/lib/asyncio_manager.py", line 219, in _wrap
    return await fn()
  File "/root/miniconda3/envs/llm/lib/python3.9/site-packages/wandb/sdk/lib/service/service_client.py", line 38, in publish
    await self._send_server_request(request)
  File "/root/miniconda3/envs/llm/lib/python3.9/site-packages/wandb/sdk/lib/service/service_client.py", line 64, in _send_server_request
    await self._writer.drain()
  File "/root/miniconda3/envs/llm/lib/python3.9/asyncio/streams.py", line 387, in drain
    await self._protocol._drain_helper()
  File "/root/miniconda3/envs/llm/lib/python3.9/asyncio/streams.py", line 190, in _drain_helper
    raise ConnectionResetError('Connection lost')
ConnectionResetError: Connection lost
2025-10-19 15:57:37,870 ERROR   MainThread:3166 [redirect.py:_on_write():664] [all runs] error in stderr callback
Traceback (most recent call last):
  File "/root/miniconda3/envs/llm/lib/python3.9/site-packages/wandb/sdk/lib/redirect.py", line 662, in _on_write
    cb(written_data)
  File "/root/miniconda3/envs/llm/lib/python3.9/site-packages/wandb/sdk/wandb_run.py", line 2436, in <lambda>
    lambda data: self._console_raw_callback("stderr", data),
  File "/root/miniconda3/envs/llm/lib/python3.9/site-packages/wandb/sdk/wandb_run.py", line 399, in wrapper
    return func(self, *args, **kwargs)
  File "/root/miniconda3/envs/llm/lib/python3.9/site-packages/wandb/sdk/wandb_run.py", line 457, in wrapper_fn
    return func(self, *args, **kwargs)
  File "/root/miniconda3/envs/llm/lib/python3.9/site-packages/wandb/sdk/wandb_run.py", line 1595, in _console_raw_callback
    self._backend.interface.publish_output_raw(name, data)
  File "/root/miniconda3/envs/llm/lib/python3.9/site-packages/wandb/sdk/interface/interface.py", line 802, in publish_output_raw
    self._publish_output_raw(o)
  File "/root/miniconda3/envs/llm/lib/python3.9/site-packages/wandb/sdk/interface/interface_shared.py", line 37, in _publish_output_raw
    self._publish(rec)
  File "/root/miniconda3/envs/llm/lib/python3.9/site-packages/wandb/sdk/interface/interface_sock.py", line 43, in _publish
    self._asyncer.run(lambda: self._client.publish(request))
  File "/root/miniconda3/envs/llm/lib/python3.9/site-packages/wandb/sdk/lib/asyncio_manager.py", line 136, in run
    return future.result()
  File "/root/miniconda3/envs/llm/lib/python3.9/concurrent/futures/_base.py", line 446, in result
    return self.__get_result()
  File "/root/miniconda3/envs/llm/lib/python3.9/concurrent/futures/_base.py", line 391, in __get_result
    raise self._exception
  File "/root/miniconda3/envs/llm/lib/python3.9/site-packages/wandb/sdk/lib/asyncio_manager.py", line 219, in _wrap
    return await fn()
  File "/root/miniconda3/envs/llm/lib/python3.9/site-packages/wandb/sdk/lib/service/service_client.py", line 38, in publish
    await self._send_server_request(request)
  File "/root/miniconda3/envs/llm/lib/python3.9/site-packages/wandb/sdk/lib/service/service_client.py", line 64, in _send_server_request
    await self._writer.drain()
  File "/root/miniconda3/envs/llm/lib/python3.9/asyncio/streams.py", line 387, in drain
    await self._protocol._drain_helper()
  File "/root/miniconda3/envs/llm/lib/python3.9/asyncio/streams.py", line 190, in _drain_helper
    raise ConnectionResetError('Connection lost')
ConnectionResetError: Connection lost
